<?xml version="1.0" ?>
<robot name="mark1" xmlns:xacro="http://www.ros.org/wiki/xacro">

<xacro:include filename="$(find rover)/urdf/materials.xacro" />
<xacro:include filename="$(find rover)/urdf/mark1.trans" />
<xacro:include filename="$(find rover)/urdf/mark1.gazebo" />
<link name="base_link">
  <inertial>
    <origin rpy="0 0 0" xyz="-0.0012050685149422157 3.5154999461666345e-18 0.009678804506941602"/>
    <mass value="0.024011514237212494"/>
    <inertia ixx="2e-06" ixy="0.0" ixz="0.0" iyy="5e-06" iyz="0.0" izz="6e-06"/>
  </inertial>
  <visual>
    <origin rpy="0 0 0" xyz="0 0 0"/>
    <geometry>
      <mesh filename="package://rover/meshes/base_link.stl" scale="0.01 0.01 0.01"/>
    </geometry>
    <material name="silver"/>
  </visual>
  <collision>
    <origin rpy="0 0 0" xyz="0 0 0"/>
    <geometry>
      <mesh filename="package://rover/meshes/base_link.stl" scale="0.01 0.01 0.01"/>
    </geometry>
  </collision>
</link>

<link name="right_wheel_1">
  <inertial>
    <origin rpy="0 0 0" xyz="-2.2351741985060514e-10 -0.0015000000000000013 -2.980232206850619e-11"/>
    <mass value="0.0005742328715937561"/>
    <inertia ixx="0.0" ixy="0.0" ixz="0.0" iyy="0.0" iyz="0.0" izz="0.0"/>
  </inertial>
  <visual>
    <origin rpy="0 0 0" xyz="0.015 0.015 -0.008014"/>
    <geometry>
      <mesh filename="package://rover/meshes/right_wheel_1.stl" scale="0.01 0.01 0.01"/>
    </geometry>
    <material name="silver"/>
  </visual>
  <collision>
    <origin rpy="0 0 0" xyz="0.015 0.015 -0.008014"/>
    <geometry>
      <mesh filename="package://rover/meshes/right_wheel_1.stl" scale="0.01 0.01 0.01"/>
    </geometry>
  </collision>
</link>

<link name="left_wheel_1">
  <inertial>
    <origin rpy="0 0 0" xyz="-2.2351741985060514e-10 0.0015000000000000013 -2.980232206850619e-11"/>
    <mass value="0.0005742328715937561"/>
    <inertia ixx="0.0" ixy="0.0" ixz="0.0" iyy="0.0" iyz="-0.0" izz="0.0"/>
  </inertial>
  <visual>
    <origin rpy="0 0 0" xyz="0.015 -0.015 -0.008014"/>
    <geometry>
      <mesh filename="package://rover/meshes/left_wheel_1.stl" scale="0.01 0.01 0.01"/>
    </geometry>
    <material name="silver"/>
  </visual>
  <collision>
    <origin rpy="0 0 0" xyz="0.015 -0.015 -0.008014"/>
    <geometry>
      <mesh filename="package://rover/meshes/left_wheel_1.stl" scale="0.01 0.01 0.01"/>
    </geometry>
  </collision>
</link>

<link name="caster_wheel_1">
  <inertial>
    <origin rpy="0 0 0" xyz="0.012000475382979797 -0.0011000000000000003 4.336808689942018e-19"/>
    <mass value="6.230825429619756e-05"/>
    <inertia ixx="0.0" ixy="-0.0" ixz="0.0" iyy="0.0" iyz="0.0" izz="0.0"/>
  </inertial>
  <visual>
    <origin rpy="0 0 0" xyz="0.000877 -0.0 -0.002514"/>
    <geometry>
      <mesh filename="package://rover/meshes/caster_wheel_1.stl" scale="0.01 0.01 0.01"/>
    </geometry>
    <material name="silver"/>
  </visual>
  <collision>
    <origin rpy="0 0 0" xyz="0.000877 -0.0 -0.002514"/>
    <geometry>
      <mesh filename="package://rover/meshes/caster_wheel_1.stl" scale="0.01 0.01 0.01"/>
    </geometry>
  </collision>
</link>


<joint name="Rigid12" type="fixed">
  <origin rpy="0 0 0" xyz="-0.000877 0.0 0.002514"/>
  <parent link="base_link"/>
  <child link="caster_wheel_1"/>
</joint>


<joint name="Rev10" type="revolute">
  <axis xyz="0.0 -1.0 0.0"/>
  <limit effort="1000.0" lower="0.0" upper="0.548" velocity="0.5"/>
  <origin rpy="0 0 0" xyz="-0.015 -0.015 0.008014"/>
  <parent link="base_link"/>
  <child link="right_wheel_1"/>
</joint>


<joint name="Rev11" type="revolute">
  <axis xyz="0.0 -1.0 0.0"/>
  <limit effort="1000.0" lower="0.0" upper="0.548" velocity="0.5"/>
  <origin rpy="0 0 0" xyz="-0.015 0.015 0.008014"/>
  <parent link="base_link"/>
  <child link="left_wheel_1"/>
</joint>





<!-- <joint name="Rev10" type="continuous">
  <origin rpy="0 0 0" xyz="-0.015 -0.015 0.008014"/>
  <parent link="base_link"/>
  <child link="right_wheel_1"/>
  <axis xyz="0.0 -1.0 0.0"/>
</joint>

<joint name="Rev11" type="continuous">
  <origin rpy="0 0 0" xyz="-0.015 0.015 0.008014"/>
  <parent link="base_link"/>
  <child link="left_wheel_1"/>
  <axis xyz="0.0 -1.0 0.0"/>
</joint>  -->









<link name="sensor_laser">
    <inertial>
        <origin xyz="0 0 0" rpy="0 0 0"/>
        <mass value="0.01"/>
        <inertia ixx="0.1" ixy="-0.1" ixz="0.0" iyy="0.0" iyz="0.0" izz="0.0"/>
    </inertial>

    <visual>
        <origin xyz="0 0 0" rpy="0 0 0" />
        <geometry>
        <cylinder radius="0.025" length="0.05"/>
        </geometry>
        <material name="silver"/>
    </visual>

    <collision>
        <origin xyz="0 0 0" rpy="0 0 0"/>
        <geometry>
        <cylinder radius="0.05" length="0.1"/>
        </geometry>
    </collision>
  </link>

  <joint name="joint_sensor_laser" type="fixed">
    <origin xyz="0.1 0 0.2" rpy="0 0 0"/>
    <parent link="base_link"/>
    <child link="sensor_laser"/>
  </joint>


</robot>
